Workbook

Sheet LAVORAZIONI
A1: LAVORAZIONI — RADIOFARMACIA PAVIA — MASTER + RIPARTIZIONE % SAL
A2: CODICE LAVORAZIONE | B2: N° OCCORRENZA | C2: MACRO AREA | D2: TIPOLOGIA IMPIANTO | E2: CATEGORIA SAL | F2: DOCUMENTO DI PROVENIENZA | G2: N. VOCE | H2: STEP DI LAVORAZIONE | I2: AREA DI INTERVENTO | J2: TIPOLOGIA DI INTERVENTO | K2: DESCRIZIONE | L2: DETTAGLI TECNICI | M2: U.M. | N2: QUANTITÀ EDITEL | O2: VALORE UNITARIO EDITEL | P2: TOTALE EDITEL | Q2: QUANTITÀ EDITEL CONSUNTIVATA | R2: VALORE UNITARIO EDITEL CONSUNTIVATO | S2: TOTALE EDITEL CONSUNTIVATO | T2: VALORE PER SAL | U2: SAL 01 APRILE 2026 | W2: SAL 02 MAGGIO 2026 | Y2: SAL 03 GIUGNO 2026 | AA2: SAL 04 LUGLIO 2026 | AC2: SAL 05 AGOSTO 2026 | AE2: SAL 06 SETTEMBRE 2026 | AG2: SAL 07 OTTOBRE 2026 | AI2: TOTALE COMPLESSIVO AVANZAMENTO
U3: % | V3: TOTALE | W3: % | X3: TOTALE | Y3: % | Z3: TOTALE | AA3: % | AB3: TOTALE | AC3: % | AD3: TOTALE | AE3: % | AF3: TOTALE | AG3: % | AH3: TOTALE | AI3: % | AJ3: TOTALE
A4: LOM241.OC.EEA.C09.A6402.NA000.0000 | B4: 1/2 | C4: EDILE | D4: NON SPECIALE | E4: EDILI | F4: 1_2025.11.20_CME REV07.PDF | G4: 1 | H4: 10 - PREPARAZIONE | I4: NUOVI LABORATORI | J4: SCAVI E MOVIMENTI TERRA | K4: OPERA: SBANCAMENTO DI TERRENO GENERICO. INCLUSO: TROVANTI ROCCIOSI/RELITTI DI MURATURE FINO A 0.750 M³. ESCLUSO: ROCCIA. | L4: OPERA: SBANCAMENTO DI TERRENO GENERICO. INCLUSO: TROVANTI ROCCIOSI/RELITTI DI MURATURE FINO A 0.750 M³. ESCLUSO: ROCCIA. LAVORO: SCAVO. INCLUSO: SPIANAMENTO E CONFIGURAZIONE FONDO ANCHE A GRADONI; PROFILATURA DI PARETI E SCARPATE; CARICO, TRASPORTO ED ACCATASTAMENTO MATERIALE IN CANTIERE. ESCLUSO: ARMO DI SCAVO; OPERE DI SEGNALAZIONE E PROTEZIONE. SPECIFICHE TECNICHE: TERRENO DI MATERIALI DI NATURA E CONSISTENZA GENERICHE TERRENO ASCIUTTO/BAGNATO/MELMOSO, PROFONDITÀ GENERICA. COMPONENTI: OP1 OPERA: SBANCAMENTO DI TERRENO GENERICO. INCLUSO: TROVANTI ROCCIOSI/RELITTI DI MURATURE FINO A 0.750 M³. ESCLUSO: ROCCIA. SPECIFICHE TECNICHE: TERRENO DI MATERIALI DI NATURA E CONSISTENZA GENERICHE TERRENO ASCIUTTO/BAGNATO/MELMOSO. RM2 TERRENO DI TERRENO GENERICO LV1 LAVORO: SCAVO. INCLUSO: SPIANAMENTO E CONFIGURAZIONE FONDO ANCHE A GRADONI; PROFILATURA DI PARETI E SCARPATE; CARICO, TRASPORTO ED ACCATASTAMENTO MATERIALE IN CANTIERE. ESCLUSO: ARMO DI SCAVO; OPERE DI SEGNALAZIONE E PROTEZIONE. SPECIFICHE TECNICHE: PROFONDITÀ GENERICA. RP2 ESCAVATORE CINGOLATO; POTENZA [KW] ≤ 90; PESO [T] ≤ 19 SPECIFICHE TECNICHE: CRITERIO DI MISURAZIONE: ORE DI PRESENZA IN CANTIERE RP2 AUTOCARRO A CASSONE RIBALTABILE; PORTATA [T] ≤ 5,0 SPECIFICHE TECNICHE: CRITERIO DI MISURAZIONE: ORE DI PRESENZA IN CANTIERE | M4: M³ | N4: 440.7 | O4: 5.88 | P4: 2591.32 | S4: =IF(AND(Q4<>"",R4<>""),Q4*R4,"") | T4: =IF(S4="",P4,S4) | U4: 1 | V4: =$T4*U4 | W4: 0 | X4: =$T4*W4 | Y4: 0 | Z4: =$T4*Y4 | AA4: 0 | AB4: =$T4*AA4 | AC4: 0 | AD4: =$T4*AC4 | AE4: 0 | AF4: =$T4*AE4 | AG4: 0 | AH4: =$T4*AG4 | AI4: =U4+W4+Y4+AA4+AC4+AE4+AG4 | AJ4: =V4+X4+Z4+AB4+AD4+AF4+AH4
A5: LOM241.1U.04.110.0040.B | B5: 1/4 | C5: EDILE | D5: NON SPECIALE | E5: EDILI | F5: 1_2025.11.20_CME REV07.PDF | G5: 2 | H5: 10 - PREPARAZIONE | I5: NUOVI LABORATORI | J5: SCAVI E MOVIMENTI TERRA | K5: COMPATTAZIONE DEL PIANO DI POSA DELLA FONDAZIONE STRADALE, NEI TRATTI IN TRINCEA, FINO A RAGGIUNGERE IN OGNI PUNTO UN VALORE DELLA DENSITÀ NON MINORE DEL 95% DI QUELLA MASSIMA DELLA PROVA AASHO MODIFI | L5: COMPATTAZIONE DEL PIANO DI POSA DELLA FONDAZIONE STRADALE, NEI TRATTI IN TRINCEA, FINO A RAGGIUNGERE IN OGNI PUNTO UN VALORE DELLA DENSITÀ NON MINORE DEL 95% DI QUELLA MASSIMA DELLA PROVA AASHO MODIFICATA, ED UN VALORE DEL MODULO DI COMPRESSIBILITÀ ME NON MINORE DI 50 N/MM², COMPRESI GLI EVENTUALI INUMIDIMENTI O ESSICAMENTI NECESSARI NEI TRATTI IN TRINCEA: - SU STRATI DI TERRENO A4, A5, A2-6, A2-7, SENZA ASPORTAZIONE O SOSTITUZIONE, MA CON EVENTUALE CORREZIONE DEI MATERIALI IN SITO PER UNA PROFONDITÀ DI CM 20, CON TERRENI ARIDI DA CONTABILIZZARE A PARTE. | M5: M² | N5: 992 | O5: 1.76 | P5: 1745.92 | S5: =IF(AND(Q5<>"",R5<>""),Q5*R5,"") | T5: =IF(S5="",P5,S5) | U5: 1 | V5: =$T5*U5 | W5: 0 | X5: =$T5*W5 | Y5: 0 | Z5: =$T5*Y5 | AA5: 0 | AB5: =$T5*AA5 | AC5: 0 | AD5: =$T5*AC5 | AE5: 0 | AF5: =$T5*AE5 | AG5: 0 | AH5: =$T5*AG5 | AI5: =U5+W5+Y5+AA5+AC5+AE5+AG5 | AJ5: =V5+X5+Z5+AB5+AD5+AF5+AH5
A6: LOM241.NC.90.050.0100.C | B6: 1/2 | C6: EDILE | D6: NON SPECIALE | E6: EDILI | F6: 1_2025.11.20_CME REV07.PDF | G6: 3 | H6: 10 - PREPARAZIONE | I6: NUOVI LABORATORI | J6: SCAVI E MOVIMENTI TERRA | K6: CARICO CON MEZZO MECCANICO DI MATERIALI SFUSI (TERRE DI SCAVO, MACERIE, INERTI ECC.), TRASPORTO E SCARICO, ALLE SEGUENTI DISTANZE DAL CANTIERE: - DA 1,1 FINO A 5 KM. | L6: CARICO CON MEZZO MECCANICO DI MATERIALI SFUSI (TERRE DI SCAVO, MACERIE, INERTI ECC.), TRASPORTO E SCARICO, ALLE SEGUENTI DISTANZE DAL CANTIERE: - DA 1,1 FINO A 5 KM. | M6: M³ | N6: 440.7 | O6: 10.58 | P6: 4662.61 | S6: =IF(AND(Q6<>"",R6<>""),Q6*R6,"") | T6: =IF(S6="",P6,S6) | U6: 1 | V6: =$T6*U6 | W6: 0 | X6: =$T6*W6 | Y6: 0 | Z6: =$T6*Y6 | AA6: 0 | AB6: =$T6*AA6 | AC6: 0 | AD6: =$T6*AC6 | AE6: 0 | AF6: =$T6*AE6 | AG6: 0 | AH6: =$T6*AG6 | AI6: =U6+W6+Y6+AA6+AC6+AE6+AG6 | AJ6: =V6+X6+Z6+AB6+AD6+AF6+AH6
A7: LOM241.1C.27.050.0100.C | B7: 1/3 | C7: EDILE | D7: NON SPECIALE | E7: EDILI | F7: 1_2025.11.20_CME REV07.PDF | G7: 4 | H7: 10 - PREPARAZIONE | I7: NUOVI LABORATORI | J7: SCAVI E MOVIMENTI TERRA | K7: ONERI PER CONFERIMENTO IN IMPIANTI AUTORIZZATI DEI SEGUENTI RIFIUTI URBANI E SPECIALI NON PERICOLOSI: - TERRE E ROCCE NON CONTENENTI SOSTANZE PERICOLOSE (CER 170504), PRESSO IMPIANTO DI RECUPERO AUTOR | L7: ONERI PER CONFERIMENTO IN IMPIANTI AUTORIZZATI DEI SEGUENTI RIFIUTI URBANI E SPECIALI NON PERICOLOSI: - TERRE E ROCCE NON CONTENENTI SOSTANZE PERICOLOSE (CER 170504), PRESSO IMPIANTO DI RECUPERO AUTORIZZATO, SECONDO IL GIUDIZIO DI AMMISSIBILITÀ IN DISCARICA RILASCIATO DAL LABORATORIO DI ANALISI AI SENSI DEL D.M. 27/09/2010 | M7: 100 KG | N7: -3439.8 | O7: 0.82 | P7: -2820.64 | S7: =IF(AND(Q7<>"",R7<>""),Q7*R7,"") | T7: =IF(S7="",P7,S7) | U7: 1 | V7: =$T7*U7 | W7: 0 | X7: =$T7*W7 | Y7: 0 | Z7: =$T7*Y7 | AA7: 0 | AB7: =$T7*AA7 | AC7: 0 | AD7: =$T7*AC7 | AE7: 0 | AF7: =$T7*AE7 | AG7: 0 | AH7: =$T7*AG7 | AI7: =U7+W7+Y7+AA7+AC7+AE7+AG7 | AJ7: =V7+X7+Z7+AB7+AD7+AF7+AH7
A8: LOM241.OC.EEA.C09.A6402.NA000.0000 | B8: 2/2 | C8: EDILE | D8: NON SPECIALE | E8: EDILI | F8: 1_2025.11.20_CME REV07.PDF | G8: 5 | H8: 10 - PREPARAZIONE | I8: NUOVI LABORATORI | J8: SCAVI E MOVIMENTI TERRA | K8: OPERA: SBANCAMENTO DI TERRENO GENERICO. INCLUSO: TROVANTI ROCCIOSI/RELITTI DI MURATURE FINO A 0.750 M³. ESCLUSO: ROCCIA. | L8: OPERA: SBANCAMENTO DI TERRENO GENERICO. INCLUSO: TROVANTI ROCCIOSI/RELITTI DI MURATURE FINO A 0.750 M³. ESCLUSO: ROCCIA. LAVORO: SCAVO. INCLUSO: SPIANAMENTO E CONFIGURAZIONE FONDO ANCHE A GRADONI; PROFILATURA DI PARETI E SCARPATE; CARICO, TRASPORTO ED ACCATASTAMENTO MATERIALE IN CANTIERE. ESCLUSO: ARMO DI SCAVO; OPERE DI SEGNALAZIONE E PROTEZIONE. SPECIFICHE TECNICHE: TERRENO DI MATERIALI DI NATURA E CONSISTENZA GENERICHE TERRENO ASCIUTTO/BAGNATO/MELMOSO, PROFONDITÀ GENERICA. COMPONENTI: OP1 OPERA: SBANCAMENTO DI TERRENO GENERICO. INCLUSO: TROVANTI ROCCIOSI/RELITTI DI MURATURE FINO A 0.750 M³. ESCLUSO: ROCCIA. SPECIFICHE TECNICHE: TERRENO DI MATERIALI DI NATURA E CONSISTENZA GENERICHE TERRENO ASCIUTTO/BAGNATO/MELMOSO. RM2 TERRENO DI TERRENO GENERICO LV1 LAVORO: SCAVO. INCLUSO: SPIANAMENTO E CONFIGURAZIONE FONDO ANCHE A GRADONI; PROFILATURA DI PARETI E SCARPATE; CARICO, TRASPORTO ED ACCATASTAMENTO MATERIALE IN CANTIERE. ESCLUSO: ARMO DI SCAVO; OPERE DI SEGNALAZIONE E PROTEZIONE. SPECIFICHE TECNICHE: PROFONDITÀ GENERICA. RP2 ESCAVATORE CINGOLATO; POTENZA [KW] ≤ 90; PESO [T] ≤ 19 SPECIFICHE TECNICHE: CRITERIO DI MISURAZIONE: ORE DI PRESENZA IN CANTIERE RP2 AUTOCARRO A CASSONE RIBALTABILE; PORTATA [T] ≤ 5,0 SPECIFICHE TECNICHE: CRITERIO DI MISURAZIONE: ORE DI PRESENZA IN CANTIERE | M8: M³ | N8: 877.5 | O8: 5.88 | P8: 5159.7 | S8: =IF(AND(Q8<>"",R8<>""),Q8*R8,"") | T8: =IF(S8="",P8,S8) | U8: 0 | V8: =$T8*U8 | W8: 0.75 | X8: =$T8*W8 | Y8: 0 | Z8: =$T8*Y8 | AA8: 0 | AB8: =$T8*AA8 | AC8: 0 | AD8: =$T8*AC8 | AE8: 0 | AF8: =$T8*AE8 | AG8: 0 | AH8: =$T8*AG8 | AI8: =U8+W8+Y8+AA8+AC8+AE8+AG8 | AJ8: =V8+X8+Z8+AB8+AD8+AF8+AH8
A9: LOM241.1U.04.110.0040.B | B9: 2/4 | C9: EDILE | D9: NON SPECIALE | E9: EDILI | F9: 1_2025.11.20_CME REV07.PDF | G9: 6 | H9: 10 - PREPARAZIONE | I9: NUOVI LABORATORI | J9: SCAVI E MOVIMENTI TERRA | K9: COMPATTAZIONE DEL PIANO DI POSA DELLA FONDAZIONE STRADALE, NEI TRATTI IN TRINCEA, FINO A RAGGIUNGERE IN OGNI PUNTO UN VALORE DELLA DENSITÀ NON MINORE DEL 95% DI QUELLA MASSIMA DELLA PROVA AASHO MODIFI | L9: COMPATTAZIONE DEL PIANO DI POSA DELLA FONDAZIONE STRADALE, NEI TRATTI IN TRINCEA, FINO A RAGGIUNGERE IN OGNI PUNTO UN VALORE DELLA DENSITÀ NON MINORE DEL 95% DI QUELLA MASSIMA DELLA PROVA AASHO MODIFICATA, ED UN VALORE DEL MODULO DI COMPRESSIBILITÀ ME NON MINORE DI 50 N/MM², COMPRESI GLI EVENTUALI INUMIDIMENTI O ESSICAMENTI NECESSARI NEI TRATTI IN TRINCEA: - SU STRATI DI TERRENO A4, A5, A2-6, A2-7, SENZA ASPORTAZIONE O SOSTITUZIONE, MA CON EVENTUALE CORREZIONE DEI MATERIALI IN SITO PER UNA PROFONDITÀ DI CM 20, CON TERRENI ARIDI DA CONTABILIZZARE A PARTE. | M9: M² | N9: 150 | O9: 1.76 | P9: 264 | S9: =IF(AND(Q9<>"",R9<>""),Q9*R9,"") | T9: =IF(S9="",P9,S9) | U9: 0 | V9: =$T9*U9 | W9: 0 | X9: =$T9*W9 | Y9: 0 | Z9: =$T9*Y9 | AA9: 0 | AB9: =$T9*AA9 | AC9: 0 | AD9: =$T9*AC9 | AE9: 0 | AF9: =$T9*AE9 | AG9: 0 | AH9: =$T9*AG9 | AI9: =U9+W9+Y9+AA9+AC9+AE9+AG9 | AJ9: =V9+X9+Z9+AB9+AD9+AF9+AH9
A10: LOM241.NC.90.050.0100.C | B10: 2/2 | C10: EDILE | D10: NON SPECIALE | E10: EDILI | F10: 1_2025.11.20_CME REV07.PDF | G10: 7 | H10: 10 - PREPARAZIONE | I10: NUOVI LABORATORI | J10: SCAVI E MOVIMENTI TERRA | K10: CARICO CON MEZZO MECCANICO DI MATERIALI SFUSI (TERRE DI SCAVO, MACERIE, INERTI ECC.), TRASPORTO E SCARICO, ALLE SEGUENTI DISTANZE DAL CANTIERE: - DA 1,1 FINO A 5 KM. | L10: CARICO CON MEZZO MECCANICO DI MATERIALI SFUSI (TERRE DI SCAVO, MACERIE, INERTI ECC.), TRASPORTO E SCARICO, ALLE SEGUENTI DISTANZE DAL CANTIERE: - DA 1,1 FINO A 5 KM. | M10: M³ | N10: 877.5 | O10: 10.58 | P10: 9283.95 | S10: =IF(AND(Q10<>"",R10<>""),Q10*R10,"") | T10: =IF(S10="",P10,S10) | U10: 0 | V10: =$T10*U10 | W10: 0.75 | X10: =$T10*W10 | Y10: 0 | Z10: =$T10*Y10 | AA10: 0 | AB10: =$T10*AA10 | AC10: 0 | AD10: =$T10*AC10 | AE10: 0 | AF10: =$T10*AE10 | AG10: 0 | AH10: =$T10*AG10 | AI10: =U10+W10+Y10+AA10+AC10+AE10+AG10 | AJ10: =V10+X10+Z10+AB10+AD10+AF10+AH10
A11: LOM241.1C.27.050.0100.C | B11: 2/3 | C11: EDILE | D11: NON SPECIALE | E11: EDILI | F11: 1_2025.11.20_CME REV07.PDF | G11: 8 | H11: 10 - PREPARAZIONE | I11: NUOVI LABORATORI | J11: SCAVI E MOVIMENTI TERRA | K11: ONERI PER CONFERIMENTO IN IMPIANTI AUTORIZZATI DEI SEGUENTI RIFIUTI URBANI E SPECIALI NON PERICOLOSI: - TERRE E ROCCE NON CONTENENTI SOSTANZE PERICOLOSE (CER 170504), PRESSO IMPIANTO DI RECUPERO AUTOR | L11: ONERI PER CONFERIMENTO IN IMPIANTI AUTORIZZATI DEI SEGUENTI RIFIUTI URBANI E SPECIALI NON PERICOLOSI: - TERRE E ROCCE NON CONTENENTI SOSTANZE PERICOLOSE (CER 170504), PRESSO IMPIANTO DI RECUPERO AUTORIZZATO, SECONDO IL GIUDIZIO DI AMMISSIBILITÀ IN DISCARICA RILASCIATO DAL LABORATORIO DI ANALISI AI SENSI DEL D.M. 27/09/2010 | M11: 100 KG | N11: 15795 | O11: 0.82 | P11: 12951.9 | S11: =IF(AND(Q11<>"",R11<>""),Q11*R11,"") | T11: =IF(S11="",P11,S11) | U11: 0 | V11: =$T11*U11 | W11: 0.75 | X11: =$T11*W11 | Y11: 0 | Z11: =$T11*Y11 | AA11: 0 | AB11: =$T11*AA11 | AC11: 0 | AD11: =$T11*AC11 | AE11: 0 | AF11: =$T11*AE11 | AG11: 0 | AH11: =$T11*AG11 | AI11: =U11+W11+Y11+AA11+AC11+AE11+AG11 | AJ11: =V11+X11+Z11+AB11+AD11+AF11+AH11
A12: LOM241.1C.27.050.0100.C | B12: 3/3 | C12: EDILE | D12: NON SPECIALE | E12: EDILI | F12: 1_2025.11.20_CME REV07.PDF | G12: 9 | H12: 10 - PREPARAZIONE | I12: NUOVI LABORATORI | J12: SCAVI E MOVIMENTI TERRA | K12: ONERI PER CONFERIMENTO IN IMPIANTI AUTORIZZATI DEI SEGUENTI RIFIUTI URBANI E SPECIALI NON PERICOLOSI: - TERRE E ROCCE NON CONTENENTI SOSTANZE PERICOLOSE (CER 170504), PRESSO IMPIANTO DI RECUPERO AUTOR | L12: ONERI PER CONFERIMENTO IN IMPIANTI AUTORIZZATI DEI SEGUENTI RIFIUTI URBANI E SPECIALI NON PERICOLOSI: - TERRE E ROCCE NON CONTENENTI SOSTANZE PERICOLOSE (CER 170504), PRESSO IMPIANTO DI RECUPERO AUTORIZZATO, SECONDO IL GIUDIZIO DI AMMISSIBILITÀ IN DISCARICA RILASCIATO DAL LABORATORIO DI ANALISI AI SENSI DEL D.M. 27/09/2010 | M12: 100 KG | N12: 15795 | O12: 0.82 | P12: 12951.9 | S12: =IF(AND(Q12<>"",R12<>""),Q12*R12,"") | T12: =IF(S12="",P12,S12) | U12: 0 | V12: =$T12*U12 | W12: 0.75 | X12: =$T12*W12 | Y12: 0 | Z12: =$T12*Y12 | AA12: 0 | AB12: =$T12*AA12 | AC12: 0 | AD12: =$T12*AC12 | AE12: 0 | AF12: =$T12*AE12 | AG12: 0 | AH12: =$T12*AG12 | AI12: =U12+W12+Y12+AA12+AC12+AE12+AG12 | AJ12: =V12+X12+Z12+AB12+AD12+AF12+AH12
A13: LOM241.OC.EEA.C09.A6400.NA000.0000.B | B13: 1/2 | C13: EDILE | D13: NON SPECIALE | E13: EDILI | F13: 1_2025.11.20_CME REV07.PDF | G13: 28 | H13: 10 - PREPARAZIONE | I13: NUOVI LABORATORI | J13: SCAVI E MOVIMENTI TERRA | K13: OPERA: SCOTICO DI TERRENO GENERICO. | L13: OPERA: SCOTICO DI TERRENO GENERICO. LAVORO: SCAVO CON MEZZI MECCANICI. INCLUSO: ESTIRPAZIONE ERBA, ARBUSTI, ALBERI DI PICCOLE DIMENSIONI; DEMOLIZIONE E RIMOZIONE RECINZIONI; CARICO E TRASPORTO TERRE AD IMPIANTO DI STOCCAGGIO, DI RECUPERO. SPECIFICHE TECNICHE: TERRENO DI NATURA GENERICA. COMPONENTI: OP1 OPERA: SCOTICO DI TERRENO GENERICO. SPECIFICHE TECNICHE: TERRENO DI NATURA GENERICA. RM2 TERRENO DI TERRENO GENERICO LV1 LAVORO: SCAVO CON MEZZI MECCANICI. INCLUSO: ESTIRPAZIONE ERBA, ARBUSTI, ALBERI DI PICCOLE DIMENSIONI; DEMOLIZIONE E RIMOZIONE RECINZIONI; CARICO E TRASPORTO TERRE AD IMPIANTO DI STOCCAGGIO, DI RECUPERO. RP2 AUTOCARRO A CASSONE RIBALTABILE; PORTATA [T] ≤ 1,5 SPECIFICHE TECNICHE: CRITERIO DI MISURAZIONE: ORE DI PRESENZA IN CANTIERE | M13: M³ | N13: 117.6 | O13: 11.76 | P13: 1382.98 | S13: =IF(AND(Q13<>"",R13<>""),Q13*R13,"") | T13: =IF(S13="",P13,S13) | U13: 0 | V13: =$T13*U13 | W13: 0.75 | X13: =$T13*W13 | Y13: 0 | Z13: =$T13*Y13 | AA13: 0 | AB13: =$T13*AA13 | AC13: 0 | AD13: =$T13*AC13 | AE13: 0 | AF13: =$T13*AE13 | AG13: 0 | AH13: =$T13*AG13 | AI13: =U13+W13+Y13+AA13+AC13+AE13+AG13 | AJ13: =V13+X13+Z13+AB13+AD13+AF13+AH13
A14: LOM241.1U.04.110.0040.B | B14: 3/4 | C14: EDILE | D14: NON SPECIALE | E14: EDILI | F14: 1_2025.11.20_CME REV07.PDF | G14: 30 | H14: 10 - PREPARAZIONE | I14: NUOVI LABORATORI | J14: SCAVI E MOVIMENTI TERRA | K14: COMPATTAZIONE DEL PIANO DI POSA DELLA FONDAZIONE STRADALE, NEI TRATTI IN TRINCEA, FINO A RAGGIUNGERE IN OGNI PUNTO UN VALORE DELLA DENSITÀ NON MINORE DEL 95% DI QUELLA MASSIMA DELLA PROVA AASHO MODIFI | L14: COMPATTAZIONE DEL PIANO DI POSA DELLA FONDAZIONE STRADALE, NEI TRATTI IN TRINCEA, FINO A RAGGIUNGERE IN OGNI PUNTO UN VALORE DELLA DENSITÀ NON MINORE DEL 95% DI QUELLA MASSIMA DELLA PROVA AASHO MODIFICATA, ED UN VALORE DEL MODULO DI COMPRESSIBILITÀ ME NON MINORE DI 50 N/MM², COMPRESI GLI EVENTUALI INUMIDIMENTI O ESSICAMENTI NECESSARI NEI TRATTI IN TRINCEA: - SU STRATI DI TERRENO A4, A5, A2-6, A2-7, SENZA ASPORTAZIONE O SOSTITUZIONE, MA CON EVENTUALE CORREZIONE DEI MATERIALI IN SITO PER UNA PROFONDITÀ DI CM 20, CON TERRENI ARIDI DA CONTABILIZZARE A PARTE. | M14: M² | N14: 395 | O14: 1.76 | P14: 695.2 | S14: =IF(AND(Q14<>"",R14<>""),Q14*R14,"") | T14: =IF(S14="",P14,S14) | U14: 0 | V14: =$T14*U14 | W14: 0 | X14: =$T14*W14 | Y14: 0 | Z14: =$T14*Y14 | AA14: 0 | AB14: =$T14*AA14 | AC14: 0 | AD14: =$T14*AC14 | AE14: 0 | AF14: =$T14*AE14 | AG14: 0 | AH14: =$T14*AG14 | AI14: =U14+W14+Y14+AA14+AC14+AE14+AG14 | AJ14: =V14+X14+Z14+AB14+AD14+AF14+AH14
A15: LOM241.OC.EEA.C09.A6400.NA000.0000.B | B15: 2/2 | C15: EDILE | D15: NON SPECIALE | E15: EDILI | F15: 1_2025.11.20_CME REV07.PDF | G15: 33 | H15: 10 - PREPARAZIONE | I15: NUOVI LABORATORI | J15: SCAVI E MOVIMENTI TERRA | K15: OPERA: SCOTICO DI TERRENO GENERICO. | L15: OPERA: SCOTICO DI TERRENO GENERICO. LAVORO: SCAVO CON MEZZI MECCANICI. INCLUSO: ESTIRPAZIONE ERBA, ARBUSTI, ALBERI DI PICCOLE DIMENSIONI; DEMOLIZIONE E RIMOZIONE RECINZIONI; CARICO E TRASPORTO TERRE AD IMPIANTO DI STOCCAGGIO, DI RECUPERO. SPECIFICHE TECNICHE: TERRENO DI NATURA GENERICA. COMPONENTI: OP1 OPERA: SCOTICO DI TERRENO GENERICO. SPECIFICHE TECNICHE: TERRENO DI NATURA GENERICA. RM2 TERRENO DI TERRENO GENERICO LV1 LAVORO: SCAVO CON MEZZI MECCANICI. INCLUSO: ESTIRPAZIONE ERBA, ARBUSTI, ALBERI DI PICCOLE DIMENSIONI; DEMOLIZIONE E RIMOZIONE RECINZIONI; CARICO E TRASPORTO TERRE AD IMPIANTO DI STOCCAGGIO, DI RECUPERO. RP2 AUTOCARRO A CASSONE RIBALTABILE; PORTATA [T] ≤ 1,5 SPECIFICHE TECNICHE: CRITERIO DI MISURAZIONE: ORE DI PRESENZA IN CANTIERE | M15: M³ | N15: 72 | O15: 11.76 | P15: 846.72 | S15: =IF(AND(Q15<>"",R15<>""),Q15*R15,"") | T15: =IF(S15="",P15,S15) | U15: 0 | V15: =$T15*U15 | W15: 0 | X15: =$T15*W15 | Y15: 0 | Z15: =$T15*Y15 | AA15: 0 | AB15: =$T15*AA15 | AC15: 0 | AD15: =$T15*AC15 | AE15: 0 | AF15: =$T15*AE15 | AG15: 0 | AH15: =$T15*AG15 | AI15: =U15+W15+Y15+AA15+AC15+AE15+AG15 | AJ15: =V15+X15+Z15+AB15+AD15+AF15+AH15
... A238: LOM251.OC.EEA.PA15.I7822.D0010.0750.J | B238: 1/2 | C238: IMPIANTO MECCANICO | D238: NON SPECIALE | E238: MECCANICHE | F238: 2_CME_TOTALE MECCANICI RADIOFARMACIA PAVIA.PDF | G238: 216/216 | H238: 40 - IMPIANTISTICO | I238: PIANO TERRA | J238: IMPIANTO IIS E FOGNA | K238: OPERA: TUBAZIONE DI SCARICO DI PLASTICA POLIETILENE AD ALTA DENSITÀ (HDPE/PEAD); FUNZIONE: SCARICO; DIAMETRO ESTERNO (Ø) [MM] = 160. | L238: OPERA: TUBAZIONE DI SCARICO DI PLASTICA POLIETILENE AD ALTA DENSITÀ (HDPE/PEAD); FUNZIONE: SCARICO; DIAMETRO ESTERNO (Ø) [MM] = 160. LAVORO: SALDATURA DI TESTA. INCLUSO: OPERAZIONI DI PREPARAZIONE DI ELEMENTI DA SALDARE; NOLO SALDATRICE; CONSUMI. SPECIFICHE TECNICHE: PEAD MALLEABILIZZATO. OP TUBAZIONE DI SCARICO DI PLASTICA POLIETILENE AD ALTA DENSITÀ (HDPE/PEAD); FUNZIONE: SCARICO; DIAMETRO ESTERNO (Ø) [MM] = 160. SPECIFICHE TECNICHE: PEAD MALLEABILIZZATO. RM TUBO DI PLASTICA POLIETILENE (PE); FINITURA: COLORE NERO; GEOMETRIA: MALLEABILIZZATO; FUNZIONE: SCARICO ACQUE; IMPIEGO: IMPIANTO CIVILE | INDUSTRIALE; DIAMETRO ESTERNO (Ø) [MM] = 160 | SPESSORE [MM] = 6,2. ESCLUSO: RACCORDI SPECIFICHE TECNICHE: DA GIUNTARE CON: SALDATURA DI TESTA, MANICOTTO ELETTRICO O MANICOTTO DI DILATAZIONE LV SALDATURA DI TESTA. INCLUSO: OPERAZIONI DI PREPARAZIONE DI ELEMENTI DA SALDARE; NOLO SALDATRICE; CONSUMI. RP SALDATRICE TESTA-TESTA; DIAMETRO OPERATIVO [MM] = 75 ÷ 250. INCLUSO: ACCESSORI (ES. FRESA SPIANATRICE, TERMOELEMENTO, CENTRALINA, TERMOSTATO, ANELLI DI RIDUZIONE). DA CONTEGGIARE A PARTE: SPESE DI ESERCIZIO (RP.01.20.00.1020.B) | M238: M | N238: 8 | O238: 67.68 | P238: 541.44 | S238: =IF(AND(Q238<>"",R238<>""),Q238*R238,"") | T238: =IF(S238="",P238,S238) | U238: 0 | V238: =$T238*U238 | W238: 0.75 | X238: =$T238*W238 | Y238: 0 | Z238: =$T238*Y238 | AA238: 0 | AB238: =$T238*AA238 | AC238: 0 | AD238: =$T238*AC238 | AE238: 0 | AF238: =$T238*AE238 | AG238: 0 | AH238: =$T238*AG238 | AI238: =U238+W238+Y238+AA238+AC238+AE238+AG238 | AJ238: =V238+X238+Z238+AB238+AD238+AF238+AH238
A239: LOM251.OC.EEA.PA02.I7816.SB030.0000 | B239: 1/1 | C239: IMPIANTO MECCANICO | D239: NON SPECIALE | E239: MECCANICHE | F239: 2_CME_TOTALE MECCANICI RADIOFARMACIA PAVIA.PDF | G239: 217/217 | H239: 40 - IMPIANTISTICO | J239: IMPIANTO ACQUE METEORICHE | K239: OPERA: PLUVIALE, TERMINALE DI LEGA FERROSA GHISA GENERICO. INCLUSO: ACCESSORI DI FISSAGGIO. | L239: OPERA: PLUVIALE, TERMINALE DI LEGA FERROSA GHISA GENERICO. INCLUSO: ACCESSORI DI FISSAGGIO. LAVORO: POSA. INCLUSO: ASSISTENZE MURARIE. OP PLUVIALE, TERMINALE DI LEGA FERROSA GHISA GENERICO. INCLUSO: ACCESSORI DI FISSAGGIO. RM TUBO TERMINALE PLUVIALE DI LEGA FERROSA GHISA GENERICO; GEOMETRIA: DRITTO; IMPIEGO: PLUVIALI; DIAMETRO (Ø) [MM] = 80 | LUNGHEZZA [M] = 1,5 LV POSA. INCLUSO: ASSISTENZE MURARIE. | M239: CAD | N239: 9 | O239: 147.84 | P239: 1330.56 | S239: =IF(AND(Q239<>"",R239<>""),Q239*R239,"") | T239: =IF(S239="",P239,S239) | U239: 0 | V239: =$T239*U239 | W239: 0.5 | X239: =$T239*W239 | Y239: 0 | Z239: =$T239*Y239 | AA239: 0 | AB239: =$T239*AA239 | AC239: 0 | AD239: =$T239*AC239 | AE239: 0 | AF239: =$T239*AE239 | AG239: 0 | AH239: =$T239*AG239 | AI239: =U239+W239+Y239+AA239+AC239+AE239+AG239 | AJ239: =V239+X239+Z239+AB239+AD239+AF239+AH239
A240: LOM251.OC.EEA.PA02.I7836.D0019.0020 | B240: 1/1 | C240: IMPIANTO MECCANICO | D240: NON SPECIALE | E240: MECCANICHE | F240: 2_CME_TOTALE MECCANICI RADIOFARMACIA PAVIA.PDF | G240: 218/218 | H240: 40 - IMPIANTISTICO | J240: IMPIANTO ACQUE METEORICHE | K240: OPERA: TUBAZIONE DI VENTILAZIONE, A BICCHIERE AD INCOLLAGGIO DI PLASTICA POLIVINCLORURO NON PLASTIFICATO (PVC-U); FINITURA: COLORE AVORIO | COLORE GRIGIO | COLORE MARRONE; IMPIEGO: VENTILAZIONE E PLUV | L240: OPERA: TUBAZIONE DI VENTILAZIONE, A BICCHIERE AD INCOLLAGGIO DI PLASTICA POLIVINCLORURO NON PLASTIFICATO (PVC-U); FINITURA: COLORE AVORIO | COLORE GRIGIO | COLORE MARRONE; IMPIEGO: VENTILAZIONE E PLUVIALI; DIAMETRO ESTERNO (Ø) [MM] = 80 | SPESSORE [MM] = 1,5. LAVORO: POSA. INCLUSO: ONERI DI FISSAGGIO A PARETE; ONERI DI FISSAGGIO A SOFFITTI; ONERI ATTRAVERSAMENTI DELLE STRUTTURE. SPECIFICHE TECNICHE: COLORE GRIGIO (RAL 7037); COLORE MARRONE (RAL 8017). OP TUBAZIONE DI VENTILAZIONE, A BICCHIERE AD INCOLLAGGIO DI PLASTICA POLIVINCLORURO NON PLASTIFICATO (PVC-U); FINITURA: COLORE AVORIO | COLORE GRIGIO | COLORE MARRONE; IMPIEGO: VENTILAZIONE E PLUVIALI; DIAMETRO ESTERNO (Ø) [MM] = 80 | SPESSORE [MM] = 1,5. SPECIFICHE TECNICHE: COLORE GRIGIO (RAL 7037); COLORE MARRONE (RAL 8017). RM TUBO A BICCHIERE AD INCOLLAGGIO DI PLASTICA POLIVINCLORURO NON PLASTIFICATO (PVC-U); FINITURA: COLORE AVORIO | COLORE GRIGIO | COLORE MARRONE; IMPIEGO: CONDOTTE DI VENTILAZIONE | PLUVIALI; DIAMETRO ESTERNO (Ø) [MM] = 80 | SPESSORE [MM] = 1,5 SPECIFICHE TECNICHE: COLORI RAL 7037 E RAL 8017 RM SISTEMA DI FISSAGGIO DI PLASTICA POLIVINILCLORURO (PVC); FUNZIONE: VENTILAZIONE | PLUVIALI; IMPIEGO: TUBO DI DIAMETRO ESTERNO [MM] = 80; SPESSORE [MM] = 1,5 LV POSA. INCLUSO: ONERI DI FISSAGGIO A PARETE; ONERI DI FISSAGGIO A SOFFITTI; ONERI ATTRAVERSAMENTI DELLE STRUTTURE. | M240: M | N240: 55 | O240: 30.36 | P240: 1669.8 | S240: =IF(AND(Q240<>"",R240<>""),Q240*R240,"") | T240: =IF(S240="",P240,S240) | U240: 0 | V240: =$T240*U240 | W240: 0.5 | X240: =$T240*W240 | Y240: 0 | Z240: =$T240*Y240 | AA240: 0 | AB240: =$T240*AA240 | AC240: 0 | AD240: =$T240*AC240 | AE240: 0 | AF240: =$T240*AE240 | AG240: 0 | AH240: =$T240*AG240 | AI240: =U240+W240+Y240+AA240+AC240+AE240+AG240 | AJ240: =V240+X240+Z240+AB240+AD240+AF240+AH240
A241: LOM251.OC.EEA.PA02.I7836.D0019.0025 | B241: 1/1 | C241: IMPIANTO MECCANICO | D241: NON SPECIALE | E241: MECCANICHE | F241: 2_CME_TOTALE MECCANICI RADIOFARMACIA PAVIA.PDF | G241: 219/219 | H241: 40 - IMPIANTISTICO | J241: IMPIANTO ACQUE METEORICHE | K241: OPERA: TUBAZIONE DI VENTILAZIONE, A BICCHIERE AD INCOLLAGGIO DI PLASTICA POLIVINCLORURO NON PLASTIFICATO (PVC-U); FINITURA: COLORE AVORIO | COLORE GRIGIO | COLORE MARRONE; IMPIEGO: VENTILAZIONE E PLUV | L241: OPERA: TUBAZIONE DI VENTILAZIONE, A BICCHIERE AD INCOLLAGGIO DI PLASTICA POLIVINCLORURO NON PLASTIFICATO (PVC-U); FINITURA: COLORE AVORIO | COLORE GRIGIO | COLORE MARRONE; IMPIEGO: VENTILAZIONE E PLUVIALI; DIAMETRO ESTERNO (Ø) [MM] = 100 | SPESSORE [MM] = 1,7. LAVORO: POSA. INCLUSO: ONERI DI FISSAGGIO A PARETE; ONERI DI FISSAGGIO A SOFFITTI; ONERI ATTRAVERSAMENTI DELLE STRUTTURE. SPECIFICHE TECNICHE: COLORE GRIGIO (RAL 7037); COLORE MARRONE (RAL 8017). OP TUBAZIONE DI VENTILAZIONE, A BICCHIERE AD INCOLLAGGIO DI PLASTICA POLIVINCLORURO NON PLASTIFICATO (PVC-U); FINITURA: COLORE AVORIO | COLORE GRIGIO | COLORE MARRONE; IMPIEGO: VENTILAZIONE E PLUVIALI; DIAMETRO ESTERNO (Ø) [MM] = 100 | SPESSORE [MM] = 1,7. SPECIFICHE TECNICHE: COLORE GRIGIO (RAL 7037); COLORE MARRONE (RAL 8017). RM TUBO A BICCHIERE AD INCOLLAGGIO DI PLASTICA POLIVINCLORURO NON PLASTIFICATO (PVC-U); FINITURA: COLORE AVORIO | COLORE GRIGIO | COLORE MARRONE; IMPIEGO: CONDOTTE DI VENTILAZIONE | PLUVIALI; DIAMETRO ESTERNO (Ø) [MM] = 100 | SPESSORE [MM] = 1,7 SPECIFICHE TECNICHE: COLORI RAL 7037 E RAL 8017 RM SISTEMA DI FISSAGGIO DI PLASTICA POLIVINILCLORURO (PVC); FUNZIONE: VENTILAZIONE | PLUVIALI; IMPIEGO: TUBO DI DIAMETRO ESTERNO [MM] = 100; SPESSORE [MM] = 1,7 LV POSA. INCLUSO: ONERI DI FISSAGGIO A PARETE; ONERI DI FISSAGGIO A SOFFITTI; ONERI ATTRAVERSAMENTI DELLE STRUTTURE. | M241: M | N241: 15 | O241: 36.37 | P241: 545.55 | S241: =IF(AND(Q241<>"",R241<>""),Q241*R241,"") | T241: =IF(S241="",P241,S241) | U241: 0 | V241: =$T241*U241 | W241: 0.5 | X241: =$T241*W241 | Y241: 0 | Z241: =$T241*Y241 | AA241: 0 | AB241: =$T241*AA241 | AC241: 0 | AD241: =$T241*AC241 | AE241: 0 | AF241: =$T241*AE241 | AG241: 0 | AH241: =$T241*AG241 | AI241: =U241+W241+Y241+AA241+AC241+AE241+AG241 | AJ241: =V241+X241+Z241+AB241+AD241+AF241+AH241
A242: LOM251.OC.EEA.PA02.I7836.D0019.0030 | B242: 1/1 | C242: IMPIANTO MECCANICO | D242: NON SPECIALE | E242: MECCANICHE | F242: 2_CME_TOTALE MECCANICI RADIOFARMACIA PAVIA.PDF | G242: 220/220 | H242: 40 - IMPIANTISTICO | J242: IMPIANTO ACQUE METEORICHE | K242: OPERA: TUBAZIONE DI VENTILAZIONE, A BICCHIERE AD INCOLLAGGIO DI PLASTICA POLIVINCLORURO NON PLASTIFICATO (PVC-U); FINITURA: COLORE AVORIO | COLORE GRIGIO | COLORE MARRONE; IMPIEGO: VENTILAZIONE E PLUV | L242: OPERA: TUBAZIONE DI VENTILAZIONE, A BICCHIERE AD INCOLLAGGIO DI PLASTICA POLIVINCLORURO NON PLASTIFICATO (PVC-U); FINITURA: COLORE AVORIO | COLORE GRIGIO | COLORE MARRONE; IMPIEGO: VENTILAZIONE E PLUVIALI; DIAMETRO ESTERNO (Ø) [MM] = 125 | SPESSORE [MM] = 2. LAVORO: POSA. INCLUSO: ONERI DI FISSAGGIO A PARETE; ONERI DI FISSAGGIO A SOFFITTI; ONERI ATTRAVERSAMENTI DELLE STRUTTURE. SPECIFICHE TECNICHE: COLORE GRIGIO (RAL 7037); COLORE MARRONE (RAL 8017). OP TUBAZIONE DI VENTILAZIONE, A BICCHIERE AD INCOLLAGGIO DI PLASTICA POLIVINCLORURO NON PLASTIFICATO (PVC-U); FINITURA: COLORE AVORIO | COLORE GRIGIO | COLORE MARRONE; IMPIEGO: VENTILAZIONE E PLUVIALI; DIAMETRO ESTERNO (Ø) [MM] = 125 | SPESSORE [MM] = 2. SPECIFICHE TECNICHE: COLORE GRIGIO (RAL 7037); COLORE MARRONE (RAL 8017). RM TUBO A BICCHIERE AD INCOLLAGGIO DI PLASTICA POLIVINCLORURO NON PLASTIFICATO (PVC-U); FINITURA: COLORE AVORIO | COLORE GRIGIO | COLORE MARRONE; IMPIEGO: CONDOTTE DI VENTILAZIONE | PLUVIALI; DIAMETRO ESTERNO (Ø) [MM] = 110 | SPESSORE [MM] = 2 SPECIFICHE TECNICHE: COLORI RAL 7037 E RAL 8017 RM SISTEMA DI FISSAGGIO DI PLASTICA POLIVINILCLORURO (PVC); FUNZIONE: VENTILAZIONE | PLUVIALI; IMPIEGO: TUBO DI DIAMETRO ESTERNO [MM] = 125; SPESSORE [MM] = 2 LV POSA. INCLUSO: ONERI DI FISSAGGIO A PARETE; ONERI DI FISSAGGIO A SOFFITTI; ONERI ATTRAVERSAMENTI DELLE STRUTTURE. | M242: M | N242: 25 | O242: 44.41 | P242: 1110.25 | S242: =IF(AND(Q242<>"",R242<>""),Q242*R242,"") | T242: =IF(S242="",P242,S242) | U242: 0 | V242: =$T242*U242 | W242: 0.5 | X242: =$T242*W242 | Y242: 0 | Z242: =$T242*Y242 | AA242: 0 | AB242: =$T242*AA242 | AC242: 0 | AD242: =$T242*AC242 | AE242: 0 | AF242: =$T242*AE242 | AG242: 0 | AH242: =$T242*AG242 | AI242: =U242+W242+Y242+AA242+AC242+AE242+AG242 | AJ242: =V242+X242+Z242+AB242+AD242+AF242+AH242
A243: LOM251.OC.EEA.PA02.I7836.D0019.0035 | B243: 1/1 | C243: IMPIANTO MECCANICO | D243: NON SPECIALE | E243: MECCANICHE | F243: 2_CME_TOTALE MECCANICI RADIOFARMACIA PAVIA.PDF | G243: 221/221 | H243: 40 - IMPIANTISTICO | J243: IMPIANTO ACQUE METEORICHE | K243: OPERA: TUBAZIONE DI VENTILAZIONE, A BICCHIERE AD INCOLLAGGIO DI PLASTICA POLIVINCLORURO NON PLASTIFICATO (PVC-U); FINITURA: COLORE AVORIO | COLORE GRIGIO | COLORE MARRONE; IMPIEGO: VENTILAZIONE E PLUV | L243: OPERA: TUBAZIONE DI VENTILAZIONE, A BICCHIERE AD INCOLLAGGIO DI PLASTICA POLIVINCLORURO NON PLASTIFICATO (PVC-U); FINITURA: COLORE AVORIO | COLORE GRIGIO | COLORE MARRONE; IMPIEGO: VENTILAZIONE E PLUVIALI; DIAMETRO ESTERNO (Ø) [MM] = 140 | SPESSORE [MM] = 2,3. LAVORO: POSA. INCLUSO: ONERI DI FISSAGGIO A PARETE; ONERI DI FISSAGGIO A SOFFITTI; ONERI ATTRAVERSAMENTI DELLE STRUTTURE. SPECIFICHE TECNICHE: COLORE GRIGIO (RAL 7037); COLORE MARRONE (RAL 8017). OP TUBAZIONE DI VENTILAZIONE, A BICCHIERE AD INCOLLAGGIO DI PLASTICA POLIVINCLORURO NON PLASTIFICATO (PVC-U); FINITURA: COLORE AVORIO | COLORE GRIGIO | COLORE MARRONE; IMPIEGO: VENTILAZIONE E PLUVIALI; DIAMETRO ESTERNO (Ø) [MM] = 140 | SPESSORE [MM] = 2,3. SPECIFICHE TECNICHE: COLORE GRIGIO (RAL 7037); COLORE MARRONE (RAL 8017). RM TUBO A BICCHIERE AD INCOLLAGGIO DI PLASTICA POLIVINCLORURO NON PLASTIFICATO (PVC-U); FINITURA: COLORE AVORIO | COLORE GRIGIO | COLORE MARRONE; IMPIEGO: CONDOTTE DI VENTILAZIONE | PLUVIALI; DIAMETRO ESTERNO (Ø) [MM] = 140 | SPESSORE [MM] = 2,3 SPECIFICHE TECNICHE: COLORI RAL 7037 E RAL 8017 RM SISTEMA DI FISSAGGIO DI PLASTICA POLIVINILCLORURO (PVC); FUNZIONE: VENTILAZIONE | PLUVIALI; IMPIEGO: TUBO DI DIAMETRO ESTERNO [MM] = 140; SPESSORE [MM] = 2,3 LV POSA. INCLUSO: ONERI DI FISSAGGIO A PARETE; ONERI DI FISSAGGIO A SOFFITTI; ONERI ATTRAVERSAMENTI DELLE STRUTTURE. | M243: M | N243: 40 | O243: 58.76 | P243: 2350.4 | S243: =IF(AND(Q243<>"",R243<>""),Q243*R243,"") | T243: =IF(S243="",P243,S243) | U243: 0 | V243: =$T243*U243 | W243: 0.5 | X243: =$T243*W243 | Y243: 0 | Z243: =$T243*Y243 | AA243: 0 | AB243: =$T243*AA243 | AC243: 0 | AD243: =$T243*AC243 | AE243: 0 | AF243: =$T243*AE243 | AG243: 0 | AH243: =$T243*AG243 | AI243: =U243+W243+Y243+AA243+AC243+AE243+AG243 | AJ243: =V243+X243+Z243+AB243+AD243+AF243+AH243
A244: LOM251.OC.EEA.PA02.I7836.D0019.0045 | B244: 1/1 | C244: IMPIANTO MECCANICO | D244: NON SPECIALE | E244: MECCANICHE | F244: 2_CME_TOTALE MECCANICI RADIOFARMACIA PAVIA.PDF | G244: 222/222 | H244: 40 - IMPIANTISTICO | J244: IMPIANTO ACQUE METEORICHE | K244: OPERA: TUBAZIONE DI VENTILAZIONE, A BICCHIERE AD INCOLLAGGIO DI PLASTICA POLIVINCLORURO NON PLASTIFICATO (PVC-U); FINITURA: COLORE AVORIO | COLORE GRIGIO | COLORE MARRONE; IMPIEGO: VENTILAZIONE E PLUV | L244: OPERA: TUBAZIONE DI VENTILAZIONE, A BICCHIERE AD INCOLLAGGIO DI PLASTICA POLIVINCLORURO NON PLASTIFICATO (PVC-U); FINITURA: COLORE AVORIO | COLORE GRIGIO | COLORE MARRONE; IMPIEGO: VENTILAZIONE E PLUVIALI; DIAMETRO ESTERNO (Ø) [MM] = 200 | SPESSORE [MM] = 3,2. LAVORO: POSA. INCLUSO: ONERI DI FISSAGGIO A PARETE; ONERI DI FISSAGGIO A SOFFITTI; ONERI ATTRAVERSAMENTI DELLE STRUTTURE. SPECIFICHE TECNICHE: COLORE GRIGIO (RAL 7037); COLORE MARRONE (RAL 8017). OP TUBAZIONE DI VENTILAZIONE, A BICCHIERE AD INCOLLAGGIO DI PLASTICA POLIVINCLORURO NON PLASTIFICATO (PVC-U); FINITURA: COLORE AVORIO | COLORE GRIGIO | COLORE MARRONE; IMPIEGO: VENTILAZIONE E PLUVIALI; DIAMETRO ESTERNO (Ø) [MM] = 200 | SPESSORE [MM] = 3,2. SPECIFICHE TECNICHE: COLORE GRIGIO (RAL 7037); COLORE MARRONE (RAL 8017). RM TUBO A BICCHIERE AD INCOLLAGGIO DI PLASTICA POLIVINCLORURO NON PLASTIFICATO (PVC-U); FINITURA: COLORE AVORIO | COLORE GRIGIO | COLORE MARRONE; IMPIEGO: CONDOTTE DI VENTILAZIONE | PLUVIALI; DIAMETRO ESTERNO (Ø) [MM] = 200 | SPESSORE [MM] = 3,2 SPECIFICHE TECNICHE: COLORI RAL 7037 E RAL 8017 RM SISTEMA DI FISSAGGIO DI PLASTICA POLIVINILCLORURO (PVC); FUNZIONE: VENTILAZIONE | PLUVIALI; IMPIEGO: TUBO DI DIAMETRO ESTERNO [MM] = 200; SPESSORE [MM] = 3,2 LV POSA. INCLUSO: ONERI DI FISSAGGIO A PARETE; ONERI DI FISSAGGIO A SOFFITTI; ONERI ATTRAVERSAMENTI DELLE STRUTTURE. | M244: M | N244: 150 | O244: 73.5 | P244: 11025 | S244: =IF(AND(Q244<>"",R244<>""),Q244*R244,"") | T244: =IF(S244="",P244,S244) | U244: 0 | V244: =$T244*U244 | W244: 0.5 | X244: =$T244*W244 | Y244: 0 | Z244: =$T244*Y244 | AA244: 0 | AB244: =$T244*AA244 | AC244: 0 | AD244: =$T244*AC244 | AE244: 0 | AF244: =$T244*AE244 | AG244: 0 | AH244: =$T244*AG244 | AI244: =U244+W244+Y244+AA244+AC244+AE244+AG244 | AJ244: =V244+X244+Z244+AB244+AD244+AF244+AH244
A245: LOM251.OC.EEA.PA02.I9730.J0001.0010 | B245: 1/1 | C245: IMPIANTO MECCANICO | D245: NON SPECIALE | E245: MECCANICHE | F245: 2_CME_TOTALE MECCANICI RADIOFARMACIA PAVIA.PDF | G245: 223/223 | H245: 40 - IMPIANTISTICO | J245: IMPIANTO ACQUE METEORICHE | K245: OPERA: POZZETTO DI CONGLOMERATO CEMENTIZIO; FUNZIONE: PER IMMISSIONE PLUVIALI; IMPIEGO: POZZETTO. INCLUSO: CALCESTRUZZO DI SOTTOFONDO, RACCORDO DELLE TUBAZIONI. | L245: OPERA: POZZETTO DI CONGLOMERATO CEMENTIZIO; FUNZIONE: PER IMMISSIONE PLUVIALI; IMPIEGO: POZZETTO. INCLUSO: CALCESTRUZZO DI SOTTOFONDO, RACCORDO DELLE TUBAZIONI. LAVORO: POSA. ESCLUSO: SCAVO; REINTERRO. OP POZZETTO DI CONGLOMERATO CEMENTIZIO; FUNZIONE: PER IMMISSIONE PLUVIALI; IMPIEGO: POZZETTO. INCLUSO: CALCESTRUZZO DI SOTTOFONDO, RACCORDO DELLE TUBAZIONI. RM POZZETTO DI CONGLOMERATO CEMENTIZIO; FUNZIONE: IMMISSIONE PLUVIALI; DIMENSIONE INTERNA X [CM] = 30 | DIMENSIONE INTERNA Y [CM] = 30 | DIMENSIONE ESTERNA X [CM] = 38 | DIMENSIONE ESTERNA Y [CM] = 54 | ALTEZZA [CM] = 40; PESO [KG] = 63 SPECIFICHE TECNICHE: POZZETTO CON CHIUSURA RM IMPASTO PRECONFEZIONATO DI CONGLOMERATO CEMENTIZIO; GEOMETRIA: SFUSO; FUNZIONE: STRUTTURALE | NON STRUTTURALE | DRENANTE; CLASSE DI CONSISTENZA [CLASSE] = S3 | CLASSE DI RESISTENZA [CLASSE] = C12/15 | CLASSE DI ESPOSIZIONE [CLASSE] = X0. COMPONENTI: LEGANTE IDRAULICO, AGGREGATO, LEGANTE IDRAULICO RICICLATO SPECIFICHE TECNICHE: UTILIZZATO IN STRUTTURE ORDINARIE E MANUFATTI NON STRUTTURALI LV POSA. ESCLUSO: SCAVO; REINTERRO. | M245: CAD | N245: 9 | O245: 308 | P245: 2772 | S245: =IF(AND(Q245<>"",R245<>""),Q245*R245,"") | T245: =IF(S245="",P245,S245) | U245: 0 | V245: =$T245*U245 | W245: 0.5 | X245: =$T245*W245 | Y245: 0 | Z245: =$T245*Y245 | AA245: 0 | AB245: =$T245*AA245 | AC245: 0 | AD245: =$T245*AC245 | AE245: 0 | AF245: =$T245*AE245 | AG245: 0 | AH245: =$T245*AG245 | AI245: =U245+W245+Y245+AA245+AC245+AE245+AG245 | AJ245: =V245+X245+Z245+AB245+AD245+AF245+AH245
A246: LOM251.OC.EEA.PA02.I9740.J0001.0010 | B246: 1/1 | C246: IMPIANTO MECCANICO | D246: NON SPECIALE | E246: MECCANICHE | F246: 2_CME_TOTALE MECCANICI RADIOFARMACIA PAVIA.PDF | G246: 224/224 | H246: 40 - IMPIANTISTICO | J246: IMPIANTO ACQUE METEORICHE | K246: OPERA: CHIUSINO DI CONGLOMERATO CEMENTIZIO; IMPIEGO: POZZETTI; LUCE INTERNA X [CM] = 45 | LUCE INTERNA Y [CM] = 45 | SPESSORE [CM] = 12; PESO [KG] = 50. | L246: OPERA: CHIUSINO DI CONGLOMERATO CEMENTIZIO; IMPIEGO: POZZETTI; LUCE INTERNA X [CM] = 45 | LUCE INTERNA Y [CM] = 45 | SPESSORE [CM] = 12; PESO [KG] = 50. LAVORO: POSA. OP CHIUSINO DI CONGLOMERATO CEMENTIZIO; IMPIEGO: POZZETTI; LUCE INTERNA X [CM] = 45 | LUCE INTERNA Y [CM] = 45 | SPESSORE [CM] = 12; PESO [KG] = 50. RM CHIUSINO DI CONGLOMERATO CEMENTIZIO; FUNZIONE: CHIUSURA; IMPIEGO: POZZETTI; LUCE INTERNA X [CM] = 45 | LUCE INTERNA Y [CM] = 45 | SPESSORE [CM] = 12; PESO [KG] = 90 SPECIFICHE TECNICHE: COMPLETO DI TELAIO RM PREMISCELATO MALTA DA INGHISAGGIO; FUNZIONE: ANTIRITIRO | PRESA RAPIDA | FISSAGGIO; IMPIEGO: ZANCHE | CHIUSINI | INFISSI | INFERRIATE; DENSITÀ [KG/M³] = 2000 SPECIFICHE TECNICHE: A BASE DI CEMENTO, INERTI SELEZIONATI, ADDITIVI; UTILIZZABILE SU TUTTI I SUPPORTI RESISTENTI LV POSA. RP AUTOCARRO CON GRU; PORTATA [T] ≤ 3. INCLUSO: ACCESSORI DI SOLLEVAMENTO. DA CONTEGGIARE A PARTE: SPESE DI ESERCIZIO (RP.00.40.15.1020.A) | M246: CAD | N246: 9 | O246: 61.6 | P246: 554.4 | S246: =IF(AND(Q246<>"",R246<>""),Q246*R246,"") | T246: =IF(S246="",P246,S246) | U246: 0 | V246: =$T246*U246 | W246: 0 | X246: =$T246*W246 | Y246: 0 | Z246: =$T246*Y246 | AA246: 0 | AB246: =$T246*AA246 | AC246: 0 | AD246: =$T246*AC246 | AE246: 0 | AF246: =$T246*AE246 | AG246: 0 | AH246: =$T246*AG246 | AI246: =U246+W246+Y246+AA246+AC246+AE246+AG246 | AJ246: =V246+X246+Z246+AB246+AD246+AF246+AH246
A247: LOM251.OC.EEA.MC09.A6401.NA000.0000.A | B247: 1/1 | C247: IMPIANTO MECCANICO | D247: NON SPECIALE | E247: MECCANICHE | F247: 2_CME_TOTALE MECCANICI RADIOFARMACIA PAVIA.PDF | G247: 225/225 | H247: 40 - IMPIANTISTICO | J247: IMPIANTO ACQUE METEORICHE | K247: OPERA: TRINCEA DI TERRA GENERICO; IMPIEGO: TUBAZIONI | COLLETTORI; PROFONDITÀ [M] ≤ 1,5. | L247: OPERA: TRINCEA DI TERRA GENERICO; IMPIEGO: TUBAZIONI | COLLETTORI; PROFONDITÀ [M] ≤ 1,5. LAVORO: SCAVO CON MEZZO MECCANICO. INCLUSO: DEPOSITO MATERIALE A BORDO SCAVO. ESCLUSO: ARMO DI SCAVO; OPERE PROVVISIONALI DI SEGNALETICA E PROTEZIONE; CARICO E TRASPORTO; ONERI DI SMALTIMENTO. SPECIFICHE TECNICHE: NON ARMATO. OP TRINCEA DI TERRA GENERICO; IMPIEGO: TUBAZIONI | COLLETTORI; PROFONDITÀ [M] ≤ 1,5. SPECIFICHE TECNICHE: NON ARMATO. RM TERRENO DI TERRA GENERICO LV SCAVO CON MEZZO MECCANICO. INCLUSO: DEPOSITO MATERIALE A BORDO SCAVO. ESCLUSO: ARMO DI SCAVO; OPERE PROVVISIONALI DI SEGNALETICA E PROTEZIONE; CARICO E TRASPORTO; ONERI DI SMALTIMENTO. RP ESCAVATORE CINGOLATO; POTENZA [KW] ≤ 90; PESO [T] = 19. DA CONTEGGIARE A PARTE: SPESE DI ESERCIZIO (RP.00.00.00.1020.D) | M247: M³ | N247: 60 | O247: 18.48 | P247: 1108.8 | S247: =IF(AND(Q247<>"",R247<>""),Q247*R247,"") | T247: =IF(S247="",P247,S247) | U247: 0 | V247: =$T247*U247 | W247: 0 | X247: =$T247*W247 | Y247: 0 | Z247: =$T247*Y247 | AA247: 0 | AB247: =$T247*AA247 | AC247: 0 | AD247: =$T247*AC247 | AE247: 0 | AF247: =$T247*AE247 | AG247: 0 | AH247: =$T247*AG247 | AI247: =U247+W247+Y247+AA247+AC247+AE247+AG247 | AJ247: =V247+X247+Z247+AB247+AD247+AF247+AH247
A248: LOM251.OC.EEA.PA04.A6600.NA000.0015 | B248: 1/1 | C248: IMPIANTO MECCANICO | D248: NON SPECIALE | E248: MECCANICHE | F248: 2_CME_TOTALE MECCANICI RADIOFARMACIA PAVIA.PDF | G248: 226/226 | H248: 40 - IMPIANTISTICO | J248: IMPIANTO ACQUE METEORICHE | K248: OPERA: REINTERRO DI TERRA GENERICO. | L248: OPERA: REINTERRO DI TERRA GENERICO. LAVORO: FORMAZIONE. INCLUSO: CARICO, TRASPORTO E SCARICO A LUOGO D'IMPIEGO; SPIANAMENTI E COSTIPAZIONE A STRATI NON SUPERIORI A 50 CM; BAGNATURA; RICARICHI. OP REINTERRO DI TERRA GENERICO. RM AGGREGATO MISTO GRANULARE DI ROCCIA NATURALE MINERALE; PESO SPECIFICO MEDIO [KG/M³] = 1800 SPECIFICHE TECNICHE: DI SABBIA E GHIAIA LV FORMAZIONE. INCLUSO: CARICO, TRASPORTO E SCARICO A LUOGO D'IMPIEGO; SPIANAMENTI E COSTIPAZIONE A STRATI NON SUPERIORI A 50 CM; BAGNATURA; RICARICHI. RP MINI ESCAVATORE CINGOLATO; POTENZA [KW] ≤ 50; PESO [T] = 9. DA CONTEGGIARE A PARTE: SPESE DI ESERCIZIO (RP.00.00.00.1010.G) RP PALA CINGOLATA; POTENZA [KW] ≤ 55. DA CONTEGGIARE A PARTE: SPESE DI ESERCIZIO (RP.00.00.05.1030.A) RP RULLO COMPRESSORE; PESO [T] = 6. ESCLUSO: TRATTORE. DA CONTEGGIARE A PARTE: SPESE DI ESERCIZIO (RP.00.10.05.1010.D) SPECIFICHE TECNICHE: TRAINATO. RP AUTOCARRO A CASSONE RIBALTABILE; PORTATA [T] = 5,01 ÷ 13,5. DA CONTEGGIARE A PARTE: SPESE DI ESERCIZIO (RP.00.50.00.1030.D) | M248: M³ | N248: 60 | O248: 9.86 | P248: 591.6 | S248: =IF(AND(Q248<>"",R248<>""),Q248*R248,"") | T248: =IF(S248="",P248,S248) | U248: 0 | V248: =$T248*U248 | W248: 0 | X248: =$T248*W248 | Y248: 0 | Z248: =$T248*Y248 | AA248: 0 | AB248: =$T248*AA248 | AC248: 0 | AD248: =$T248*AC248 | AE248: 0 | AF248: =$T248*AE248 | AG248: 0 | AH248: =$T248*AG248 | AI248: =U248+W248+Y248+AA248+AC248+AE248+AG248 | AJ248: =V248+X248+Z248+AB248+AD248+AF248+AH248
A249: DEI_IT_035316F | B249: 1/2 | C249: IMPIANTO MECCANICO | D249: NON SPECIALE | E249: MECCANICHE | F249: 2_CME_TOTALE MECCANICI RADIOFARMACIA PAVIA.PDF | G249: 121/121 | H249: 50 - INSTALLAZIONE | I249: P. TERRA - UFFICI | J249: IMPIANTO HVAC | K249: RECUPERATORE DI CALORE CENTRALIZZATO INSTALLATO A PARETE INTERNA O SOFFITTO, CON SCAMBIATORE A FLUSSI INCROCIATI IN CONTROCORRENTE, COMPLETO DI FILTRI SINTETICI POSIZIONATI SULL'ASPIRAZIONE DELL'ARIA | L249: RECUPERATORE DI CALORE CENTRALIZZATO INSTALLATO A PARETE INTERNA O SOFFITTO, CON SCAMBIATORE A FLUSSI INCROCIATI IN CONTROCORRENTE, COMPLETO DI FILTRI SINTETICI POSIZIONATI SULL'ASPIRAZIONE DELL'ARIA ESPULSA E SULLA PRESA D'ARIA ESTERNA, MOTORE CON ALIMENTAZIONE ELETTRICA 230 V-1-50 HZ, IN OPERA COMPRESI ACCESSORI ED ESCLUSI COLLEGAMENTI ELETTRICI: SCAMBIATORE DI CALORE SENSIBILE, DELLE SEGUENTI PORTATE NOMINALI: 600 MC/H | M249: CAD | N249: 1 | O249: 2703.76 | P249: 2703.76 | S249: =IF(AND(Q249<>"",R249<>""),Q249*R249,"") | T249: =IF(S249="",P249,S249) | U249: 0.5 | V249: =$T249*U249 | W249: 0.2 | X249: =$T249*W249 | Y249: 0 | Z249: =$T249*Y249 | AA249: 0 | AB249: =$T249*AA249 | AC249: 0 | AD249: =$T249*AC249 | AE249: 0 | AF249: =$T249*AE249 | AG249: 0 | AH249: =$T249*AG249 | AI249: =U249+W249+Y249+AA249+AC249+AE249+AG249 | AJ249: =V249+X249+Z249+AB249+AD249+AF249+AH249
A250: DEI_IT_035316F | B250: 2/2 | C250: IMPIANTO MECCANICO | D250: NON SPECIALE | E250: MECCANICHE | F250: 2_CME_TOTALE MECCANICI RADIOFARMACIA PAVIA.PDF | G250: 135/135 | H250: 50 - INSTALLAZIONE | I250: P. PRIMO - UFFICI | J250: IMPIANTO HVAC | K250: RECUPERATORE DI CALORE CENTRALIZZATO INSTALLATO A PARETE INTERNA O SOFFITTO, CON SCAMBIATORE A FLUSSI INCROCIATI IN CONTROCORRENTE, COMPLETO DI FILTRI SINTETICI POSIZIONATI SULL'ASPIRAZIONE DELL'ARIA | L250: RECUPERATORE DI CALORE CENTRALIZZATO INSTALLATO A PARETE INTERNA O SOFFITTO, CON SCAMBIATORE A FLUSSI INCROCIATI IN CONTROCORRENTE, COMPLETO DI FILTRI SINTETICI POSIZIONATI SULL'ASPIRAZIONE DELL'ARIA ESPULSA E SULLA PRESA D'ARIA ESTERNA, MOTORE CON ALIMENTAZIONE ELETTRICA 230 V-1-50 HZ, IN OPERA COMPRESI ACCESSORI ED ESCLUSI COLLEGAMENTI ELETTRICI: SCAMBIATORE DI CALORE SENSIBILE, DELLE SEGUENTI PORTATE NOMINALI: 600 MC/H | M250: CAD | N250: 1 | O250: 2745.01 | P250: 2745.01 | S250: =IF(AND(Q250<>"",R250<>""),Q250*R250,"") | T250: =IF(S250="",P250,S250) | U250: 0 | V250: =$T250*U250 | W250: 0.7 | X250: =$T250*W250 | Y250: 0 | Z250: =$T250*Y250 | AA250: 0 | AB250: =$T250*AA250 | AC250: 0 | AD250: =$T250*AC250 | AE250: 0 | AF250: =$T250*AE250 | AG250: 0 | AH250: =$T250*AG250 | AI250: =U250+W250+Y250+AA250+AC250+AE250+AG250 | AJ250: =V250+X250+Z250+AB250+AD250+AF250+AH250
A251: NP.IM.01 | B251: 1/2 | C251: IMPIANTO MECCANICO | D251: NON SPECIALE | E251: MECCANICHE | F251: 2_CME_TOTALE MECCANICI RADIOFARMACIA PAVIA.PDF | G251: 176/176 | H251: 50 - INSTALLAZIONE | I251: CENTRALE | J251: IMPIANTO HVAC | K251: FORNITURA E POSA IN OPERA DI POMPS DI CALORE POLIVALENTE CON CONDENSAZIONE AD ARIA, CERTIFICATO EUROVENT, COSTRUITO SECONDO STANDARD DI QUALITÀ ISO 9001, PER INSTALLAZIONE ESTERNA | L251: FORNITURA E POSA IN OPERA DI POMPS DI CALORE POLIVALENTE CON CONDENSAZIONE AD ARIA, CERTIFICATO EUROVENT, COSTRUITO SECONDO STANDARD DI QUALITÀ ISO 9001, PER INSTALLAZIONE ESTERNA CONDIZIONI DI LAVORO: ARIA INGRESSO SCAMBIATORE ESTERNO: +35°C - ACQUA: +7°/+12°C POTENZIALITÀ FRIGORIFERA: 250 KW ARIA INGRESSO SCAMBIATORE ESTERNO: +7°C - ACQUA: +45°/+40°C POTENZIALITÀ TERMICA: 250 KW | M251: CADAUNO | N251: 0.1 | O251: 95343.27 | P251: 9534.33 | S251: =IF(AND(Q251<>"",R251<>""),Q251*R251,"") | T251: =IF(S251="",P251,S251) | U251: 0 | V251: =$T251*U251 | W251: 0.5 | X251: =$T251*W251 | Y251: 0 | Z251: =$T251*Y251 | AA251: 0 | AB251: =$T251*AA251 | AC251: 0 | AD251: =$T251*AC251 | AE251: 0 | AF251: =$T251*AE251 | AG251: 0 | AH251: =$T251*AG251 | AI251: =U251+W251+Y251+AA251+AC251+AE251+AG251 | AJ251: =V251+X251+Z251+AB251+AD251+AF251+AH251
A252: DEI_IT_025264B | B252: 1/2 | C252: IMPIANTO MECCANICO | D252: NON SPECIALE | E252: MECCANICHE | F252: 2_CME_TOTALE MECCANICI RADIOFARMACIA PAVIA.PDF | G252: 177/177 | H252: 50 - INSTALLAZIONE | I252: CENTRALE | J252: IMPIANTO HVAC | K252: POMPA DI CIRCOLAZIONE IN-LINE A MOTORE VENTILATO A 4 POLI AD ALTO RENDIMENTO (IE3), ATTACCHI FLANGIATI, CORPO IN GHISA, PER IL CONVOGLIAMENTO DI ACQUA FREDDA E CALDA (TEMPERATURA LIQUIDO -20 °C ÷ +120 | L252: POMPA DI CIRCOLAZIONE IN-LINE A MOTORE VENTILATO A 4 POLI AD ALTO RENDIMENTO (IE3), ATTACCHI FLANGIATI, CORPO IN GHISA, PER IL CONVOGLIAMENTO DI ACQUA FREDDA E CALDA (TEMPERATURA LIQUIDO -20 °C ÷ +120 °C), PN 10, GRADO DI PROTEZIONE IP 55, CLASSE DI ISOLAMENTO F, ALIMENTAZIONE ELETTRICA 230/400 V, COMPRESI ACCESSORI DI MONTAGGIO, ESCLUSO IL COLLEGAMENTO ELETTRICO: POTENZA ELETTRICA 1,1 KW, Ø ATTACCO 80 MM | M252: CAD | N252: 4 | O252: 2669.15 | P252: 10676.6 | S252: =IF(AND(Q252<>"",R252<>""),Q252*R252,"") | T252: =IF(S252="",P252,S252) | U252: 0.5 | V252: =$T252*U252 | W252: 0.1 | X252: =$T252*W252 | Y252: 0 | Z252: =$T252*Y252 | AA252: 0 | AB252: =$T252*AA252 | AC252: 0 | AD252: =$T252*AC252 | AE252: 0 | AF252: =$T252*AE252 | AG252: 0 | AH252: =$T252*AG252 | AI252: =U252+W252+Y252+AA252+AC252+AE252+AG252 | AJ252: =V252+X252+Z252+AB252+AD252+AF252+AH252
A253: LOM251.OC.EEA.PA01.I8000.SB038.0055 | B253: 1/2 | C253: IMPIANTO MECCANICO | D253: NON SPECIALE | E253: MECCANICHE | F253: 2_CME_TOTALE MECCANICI RADIOFARMACIA PAVIA.PDF | G253: 178/178 | H253: 50 - INSTALLAZIONE | I253: CENTRALE | J253: IMPIANTO HVAC | K253: OPERA: SERBATOIO, INERZIALE DI LEGA FERROSA ACCIAIO NERO; FINITURA: VERNICIATO | ANTIRUGGINE; GEOMETRIA: VERTICALE; FUNZIONE: ACCUMULO ACQUA REFRIGERATA; IMPIEGO: CENTRALE IDRICA; PRESSIONE MASSIMA DI | L253: OPERA: SERBATOIO, INERZIALE DI LEGA FERROSA ACCIAIO NERO; FINITURA: VERNICIATO | ANTIRUGGINE; GEOMETRIA: VERTICALE; FUNZIONE: ACCUMULO ACQUA REFRIGERATA; IMPIEGO: CENTRALE IDRICA; PRESSIONE MASSIMA DI ESERCIZIO [BAR] = 6; CAPACITÀ [L] = 1500. LAVORO: INSTALLAZIONE. SPECIFICHE TECNICHE: SERBATOIO CON VERNICIATURA ESTERNA ANTIRUGGINE. OP SERBATOIO, INERZIALE DI LEGA FERROSA ACCIAIO NERO; FINITURA: VERNICIATO | ANTIRUGGINE; GEOMETRIA: VERTICALE; FUNZIONE: ACCUMULO ACQUA REFRIGERATA; IMPIEGO: CENTRALE IDRICA; PRESSIONE MASSIMA DI ESERCIZIO [BAR] = 6; CAPACITÀ [L] = 1500. SPECIFICHE TECNICHE: SERBATOIO CON VERNICIATURA ESTERNA ANTIRUGGINE. RM SERBATOIO INERZIALE DI LEGA FERROSA ACCIAIO NERO; FINITURA: VERNICIATO | ANTIRUGGINE; GEOMETRIA: VERTICALE; FUNZIONE: ACCUMULO ACQUA REFRIGERATA; IMPIEGO: CENTRALE IDRICA; PRESSIONE MASSIMA DI ESERCIZIO [BAR] = 6; CAPACITÀ [L] = 1500. COMPONENTE: LASTRA, SPECIFICHE TECNICHE: SERBATOIO CON VERNICIATURA ESTERNA ANTIRUGGINE LV INSTALLAZIONE. | M253: CAD | N253: 0.2 | O253: 1897.38 | P253: 379.48 | S253: =IF(AND(Q253<>"",R253<>""),Q253*R253,"") | T253: =IF(S253="",P253,S253) | U253: 0 | V253: =$T253*U253 | W253: 0.5 | X253: =$T253*W253 | Y253: 0 | Z253: =$T253*Y253 | AA253: 0 | AB253: =$T253*AA253 | AC253: 0 | AD253: =$T253*AC253 | AE253: 0 | AF253: =$T253*AE253 | AG253: 0 | AH253: =$T253*AG253 | AI253: =U253+W253+Y253+AA253+AC253+AE253+AG253 | AJ253: =V253+X253+Z253+AB253+AD253+AF253+AH253
A254: LOM251.OC.EEA.PA01.I8000.SB038.0015 | B254: 1/2 | C254: IMPIANTO MECCANICO | D254: NON SPECIALE | E254: MECCANICHE | F254: 2_CME_TOTALE MECCANICI RADIOFARMACIA PAVIA.PDF | G254: 179/179 | H254: 50 - INSTALLAZIONE | I254: CENTRALE | J254: IMPIANTO HVAC | K254: OPERA: SERBATOIO, INERZIALE DI LEGA FERROSA ACCIAIO NERO; FINITURA: VERNICIATO | ANTIRUGGINE; GEOMETRIA: VERTICALE; FUNZIONE: ACCUMULO ACQUA CALDA; IMPIEGO: CENTRALE IDRICA; PRESSIONE DI BOLLO [BAR] = | L254: OPERA: SERBATOIO, INERZIALE DI LEGA FERROSA ACCIAIO NERO; FINITURA: VERNICIATO | ANTIRUGGINE; GEOMETRIA: VERTICALE; FUNZIONE: ACCUMULO ACQUA CALDA; IMPIEGO: CENTRALE IDRICA; PRESSIONE DI BOLLO [BAR] = 12; CAPACITÀ [L] = 1500. LAVORO: INSTALLAZIONE. SPECIFICHE TECNICHE: SERBATOIO CON VERNICIATURA ESTERNA ANTIRUGGINE; TEMPERATURA MASSIMA DI ESERCIZIO [°C] = 99. OP SERBATOIO, INERZIALE DI LEGA FERROSA ACCIAIO NERO; FINITURA: VERNICIATO | ANTIRUGGINE; GEOMETRIA: VERTICALE; FUNZIONE: ACCUMULO ACQUA CALDA; IMPIEGO: CENTRALE IDRICA; PRESSIONE DI BOLLO [BAR] = 12; CAPACITÀ [L] = 1500. SPECIFICHE TECNICHE: SERBATOIO CON VERNICIATURA ESTERNA ANTIRUGGINE; TEMPERATURA MASSIMA DI ESERCIZIO [°C] = 99. RM SERBATOIO INERZIALE DI LEGA FERROSA ACCIAIO NERO; FINITURA: VERNICIATO | ANTIRUGGINE; GEOMETRIA: VERTICALE; FUNZIONE: ACCUMULO ACQUA CALDA; IMPIEGO: CENTRALE IDRICA; PRESSIONE MASSIMA DI ESERCIZIO [BAR] = 6; CAPACITÀ [L] = 1500. COMPONENTE: LASTRA, SPECIFICHE TECNICHE: SERBATOIO CON VERNICIATURA ESTERNA ANTIRUGGINE; TEMPERATURA MASSIMA DI ESERCIZIO [°C] = 99 LV INSTALLAZIONE. | M254: CAD | N254: 0.2 | O254: 1897.38 | P254: 379.48 | S254: =IF(AND(Q254<>"",R254<>""),Q254*R254,"") | T254: =IF(S254="",P254,S254) | U254: 0 | V254: =$T254*U254 | W254: 0.5 | X254: =$T254*W254 | Y254: 0 | Z254: =$T254*Y254 | AA254: 0 | AB254: =$T254*AA254 | AC254: 0 | AD254: =$T254*AC254 | AE254: 0 | AF254: =$T254*AE254 | AG254: 0 | AH254: =$T254*AG254 | AI254: =U254+W254+Y254+AA254+AC254+AE254+AG254 | AJ254: =V254+X254+Z254+AB254+AD254+AF254+AH254
A255: LOM251.OC.EEA.PA02.I9762.SB001.0965 | B255: 1/2 | C255: IMPIANTO MECCANICO | D255: NON SPECIALE | E255: MECCANICHE | F255: 2_CME_TOTALE MECCANICI RADIOFARMACIA PAVIA.PDF | G255: 185/185 | H255: 50 - INSTALLAZIONE | I255: CENTRALE | J255: IMPIANTO HVAC | K255: OPERA: VALVOLA DI LEGA FERROSA ACCIAIO GENERICO; GEOMETRIA: A DISCO | TIPO WAFER; FUNZIONE: DI RITEGNO; DIAMETRO NOMINALE (Ø) [MM] = 40; PRESSIONE NOMINALE [BAR] = 10 ÷ 40. INCLUSO: MOLLA DI LEGA FERR | L255: OPERA: VALVOLA DI LEGA FERROSA ACCIAIO GENERICO; GEOMETRIA: A DISCO | TIPO WAFER; FUNZIONE: DI RITEGNO; DIAMETRO NOMINALE (Ø) [MM] = 40; PRESSIONE NOMINALE [BAR] = 10 ÷ 40. INCLUSO: MOLLA DI LEGA FERROSA ACCIAIO INOX;. LAVORO: POSA. SPECIFICHE TECNICHE: VALVOLA CON: CORPO DI LEGA FERROSA ACCIAIO GALVANIZZATO, DISCO DI LEGA FERROSA ACCIAIO INOX, ANELLO SEDE DI TENUTA VALVOLA DI LEGA FERROSA ACCIAIO INOX. OP VALVOLA DI LEGA FERROSA ACCIAIO GENERICO; GEOMETRIA: A DISCO | TIPO WAFER; FUNZIONE: DI RITEGNO; DIAMETRO NOMINALE (Ø) [MM] = 40; PRESSIONE NOMINALE [BAR] = 10 ÷ 40. INCLUSO: MOLLA DI LEGA FERROSA ACCIAIO INOX;. SPECIFICHE TECNICHE: VALVOLA CON: CORPO DI LEGA FERROSA ACCIAIO GALVANIZZATO, DISCO DI LEGA FERROSA ACCIAIO INOX, ANELLO SEDE DI TENUTA VALVOLA DI LEGA FERROSA ACCIAIO INOX. RM VALVOLA DI LEGA FERROSA ACCIAIO GENERICO; GEOMETRIA: A DISCO | TIPO WAFER; FUNZIONE: DI RITEGNO; DIAMETRO NOMINALE (Ø) [MM] = 40; PRESSIONE NOMINALE [BAR] = 10 ÷ 40. INCLUSO: MOLLA DI LEGA FERROSA ACCIAIO INOX; SPECIFICHE TECNICHE: VALVOLA CON: CORPO DI LEGA FERROSA ACCIAIO GALVANIZZATO, DISCO DI LEGA FERROSA ACCIAIO INOX, ANELLO SEDE DI TENUTA VALVOLA DI LEGA FERROSA ACCIAIO INOX LV POSA. | M255: CAD | N255: 1 | O255: 82.86 | P255: 82.86 | S255: =IF(AND(Q255<>"",R255<>""),Q255*R255,"") | T255: =IF(S255="",P255,S255) | U255: 0 | V255: =$T255*U255 | W255: 0 | X255: =$T255*W255 | Y255: 0 | Z255: =$T255*Y255 | AA255: 0 | AB255: =$T255*AA255 | AC255: 0 | AD255: =$T255*AC255 | AE255: 0 | AF255: =$T255*AE255 | AG255: 0 | AH255: =$T255*AG255 | AI255: =U255+W255+Y255+AA255+AC255+AE255+AG255 | AJ255: =V255+X255+Z255+AB255+AD255+AF255+AH255
A256: DEI_IT_015091A | B256: 1/1 | C256: IMPIANTO MECCANICO | D256: NON SPECIALE | E256: MECCANICHE | F256: 2_CME_TOTALE MECCANICI RADIOFARMACIA PAVIA.PDF | G256: 193/193 | H256: 50 - INSTALLAZIONE | I256: CENTRALE | J256: IMPIANTO IIS E FOGNA | K256: SCALDA ACQUA A POMPA DI CALORE ARIA-ACQUA PER LA PRODUZIONE DI ACQUA CALDA SANITARIA, IN ACCIAIO INOX, PER INSTALLAZIONE A BASAMENTO (CLASSE A+ DI EFFICIENZA ENERGETICA SECONDO ERP), CON COIBENTAZIONE | L256: SCALDA ACQUA A POMPA DI CALORE ARIA-ACQUA PER LA PRODUZIONE DI ACQUA CALDA SANITARIA, IN ACCIAIO INOX, PER INSTALLAZIONE A BASAMENTO (CLASSE A+ DI EFFICIENZA ENERGETICA SECONDO ERP), CON COIBENTAZIONE IN POLIURETANO ESPANSO, ALIMENTAZIONE ELETTRICA 230 V - 50 HZ, POSTO IN OPERA ALLACCIATO ALLA RETE IDRICA CON ESCLUSIONE DEI COLLEGAMENTI ELETTRICI: SENZA SERPENTINO DI INTEGRAZIONE, DELLA CAPACITÀ DI: 200 L | M256: CAD | N256: 1 | O256: 2229.42 | P256: 2229.42 | S256: =IF(AND(Q256<>"",R256<>""),Q256*R256,"") | T256: =IF(S256="",P256,S256) | U256: 0.5 | V256: =$T256*U256 | W256: 0.1 | X256: =$T256*W256 | Y256: 0 | Z256: =$T256*Y256 | AA256: 0 | AB256: =$T256*AA256 | AC256: 0 | AD256: =$T256*AC256 | AE256: 0 | AF256: =$T256*AE256 | AG256: 0 | AH256: =$T256*AG256 | AI256: =U256+W256+Y256+AA256+AC256+AE256+AG256 | AJ256: =V256+X256+Z256+AB256+AD256+AF256+AH256
A257: LOM251.OC.EEA.PA01.I7450.ZA001.0010 | B257: 1/1 | C257: IMPIANTO MECCANICO | D257: SPECIALE | E257: MECCANICHE SPECIALI | F257: 2_CME_TOTALE MECCANICI RADIOFARMACIA PAVIA.PDF | G257: 6/6 | H257: 40 - IMPIANTISTICO | I257: CENTRALE | J257: IMPIANTO HVAC | K257: OPERA: CIRCOLATORE, GEMELLARE; FUNZIONE: DISTRIBUZIONE ACQUA; IMPIEGO: CENTRALE IDRICA; PRESSIONE NOMINALE [BAR] = 6 | PREVALENZA [KPA] = 40,1 ÷ 80 | PORTATA [M³/H] ≤ 4. | L257: OPERA: CIRCOLATORE, GEMELLARE; FUNZIONE: DISTRIBUZIONE ACQUA; IMPIEGO: CENTRALE IDRICA; PRESSIONE NOMINALE [BAR] = 6 | PREVALENZA [KPA] = 40,1 ÷ 80 | PORTATA [M³/H] ≤ 4. LAVORO: INSTALLAZIONE. SPECIFICHE TECNICHE: PRESTAZIONI MISURATE A VELOCITÀ MASSIMA. OP CIRCOLATORE, GEMELLARE; FUNZIONE: DISTRIBUZIONE ACQUA; IMPIEGO: CENTRALE IDRICA; PRESSIONE NOMINALE [BAR] = 6 | PREVALENZA [KPA] = 40,1 ÷ 80 | PORTATA [M³/H] ≤ 4. SPECIFICHE TECNICHE: PRESTAZIONI MISURATE A VELOCITÀ MASSIMA. RM CIRCOLATORE GEMELLARE; FUNZIONE: DISTRIBUZIONE ACQUA; IMPIEGO: CENTRALE IDRICA; PRESSIONE NOMINALE [BAR] = 6 | PREVALENZA [KPA] = 40,1 ÷ 80 | PORTATA [M³/H] ≤ 4. COMPONENTE: MOTORE TRIFASE (3F), SPECIFICHE TECNICHE: PRESTAZIONI MISURATE A VELOCITÀ MASSIMA LV INSTALLAZIONE. | M257: CAD | N257: 1 | O257: 2146.41 | P257: 2146.41 | S257: =IF(AND(Q257<>"",R257<>""),Q257*R257,"") | T257: =IF(S257="",P257,S257) | U257: 0 | V257: =$T257*U257 | W257: 0.7 | X257: =$T257*W257 | Y257: 0 | Z257: =$T257*Y257 | AA257: 0 | AB257: =$T257*AA257 | AC257: 0 | AD257: =$T257*AC257 | AE257: 0 | AF257: =$T257*AE257 | AG257: 0 | AH257: =$T257*AG257 | AI257: =U257+W257+Y257+AA257+AC257+AE257+AG257 | AJ257: =V257+X257+Z257+AB257+AD257+AF257+AH257
A258: LOM251.OC.EEA.PA02.I7407.SB038.0255 | B258: 3/3 | C258: IMPIANTO MECCANICO | D258: SPECIALE | E258: MECCANICHE SPECIALI | F258: 2_CME_TOTALE MECCANICI RADIOFARMACIA PAVIA.PDF | G258: 10/10 | H258: 40 - IMPIANTISTICO | I258: CENTRALE | J258: IMPIANTO HVAC | K258: OPERA: TUBAZIONE DI LEGA FERROSA ACCIAIO NERO; GEOMETRIA: FILETTATO | SERIE LEGGERA; FUNZIONE: DISTRIBUZIONE ACQUA; IMPIEGO: RETE IDRICA; DIAMETRO NOMINALE (Ø) [MM] = 20 | SPESSORE [MM] = 2,3. | L258: OPERA: TUBAZIONE DI LEGA FERROSA ACCIAIO NERO; GEOMETRIA: FILETTATO | SERIE LEGGERA; FUNZIONE: DISTRIBUZIONE ACQUA; IMPIEGO: RETE IDRICA; DIAMETRO NOMINALE (Ø) [MM] = 20 | SPESSORE [MM] = 2,3. LAVORO: POSA. SPECIFICHE TECNICHE: TUBO SENZA SALDATURA. OP TUBAZIONE DI LEGA FERROSA ACCIAIO NERO; GEOMETRIA: FILETTATO | SERIE LEGGERA; FUNZIONE: DISTRIBUZIONE ACQUA; IMPIEGO: RETE IDRICA; DIAMETRO NOMINALE (Ø) [MM] = 20 | SPESSORE [MM] = 2,3. SPECIFICHE TECNICHE: TUBO SENZA SALDATURA. RM TUBO DI LEGA FERROSA ACCIAIO NERO; GEOMETRIA: FILETTATO | SERIE LEGGERA; FUNZIONE: DISTRIBUZIONE ACQUA; IMPIEGO: RETE IDRICA; DIAMETRO NOMINALE (Ø) [MM] = 20 | SPESSORE [MM] = 2,3 SPECIFICHE TECNICHE: TUBO SENZA SALDATURA LV POSA. | M258: M | N258: 45 | O258: 24.52 | P258: 1103.4 | S258: =IF(AND(Q258<>"",R258<>""),Q258*R258,"") | T258: =IF(S258="",P258,S258) | U258: 0 | V258: =$T258*U258 | W258: 0.25 | X258: =$T258*W258 | Y258: 0 | Z258: =$T258*Y258 | AA258: 0 | AB258: =$T258*AA258 | AC258: 0 | AD258: =$T258*AC258 | AE258: 0 | AF258: =$T258*AE258 | AG258: 0 | AH258: =$T258*AG258 | AI258: =U258+W258+Y258+AA258+AC258+AE258+AG258 | AJ258: =V258+X258+Z258+AB258+AD258+AF258+AH258
A259: LOM251.OC.EEA.PA02.I7407.SB038.0295 | B259: 2/2 | C259: IMPIANTO MECCANICO | D259: SPECIALE | E259: MECCANICHE SPECIALI | F259: 2_CME_TOTALE MECCANICI RADIOFARMACIA PAVIA.PDF | G259: 11/11 | H259: 40 - IMPIANTISTICO | I259: CENTRALE | J259: IMPIANTO HVAC | K259: OPERA: TUBAZIONE DI LEGA FERROSA ACCIAIO NERO; FUNZIONE: DISTRIBUZIONE ACQUA; IMPIEGO: RETE IDRICA; DIAMETRO NOMINALE (Ø) [MM] = 25 | SPESSORE [MM] = 2,3. | L259: OPERA: TUBAZIONE DI LEGA FERROSA ACCIAIO NERO; FUNZIONE: DISTRIBUZIONE ACQUA; IMPIEGO: RETE IDRICA; DIAMETRO NOMINALE (Ø) [MM] = 25 | SPESSORE [MM] = 2,3. LAVORO: POSA. SPECIFICHE TECNICHE: TUBO SENZA SALDATURA. OP TUBAZIONE DI LEGA FERROSA ACCIAIO NERO; FUNZIONE: DISTRIBUZIONE ACQUA; IMPIEGO: RETE IDRICA; DIAMETRO NOMINALE (Ø) [MM] = 25 | SPESSORE [MM] = 2,3. SPECIFICHE TECNICHE: TUBO SENZA SALDATURA. RM TUBO DI LEGA FERROSA ACCIAIO NERO; FUNZIONE: DISTRIBUZIONE ACQUA; IMPIEGO: RETE IDRICA; DIAMETRO NOMINALE (Ø) [MM] = 25 | SPESSORE [MM] = 2,3 SPECIFICHE TECNICHE: TUBO SENZA SALDATURA LV POSA. | M259: M | N259: 15 | O259: 27.97 | P259: 419.55 | S259: =IF(AND(Q259<>"",R259<>""),Q259*R259,"") | T259: =IF(S259="",P259,S259) | U259: 0 | V259: =$T259*U259 | W259: 0.25 | X259: =$T259*W259 | Y259: 0 | Z259: =$T259*Y259 | AA259: 0 | AB259: =$T259*AA259 | AC259: 0 | AD259: =$T259*AC259 | AE259: 0 | AF259: =$T259*AE259 | AG259: 0 | AH259: =$T259*AG259 | AI259: =U259+W259+Y259+AA259+AC259+AE259+AG259 | AJ259: =V259+X259+Z259+AB259+AD259+AF259+AH259
A260: LOM251.OC.EEA.PA02.I7407.SB038.0300 | B260: 1/1 | C260: IMPIANTO MECCANICO | D260: SPECIALE | E260: MECCANICHE SPECIALI | F260: 2_CME_TOTALE MECCANICI RADIOFARMACIA PAVIA.PDF | G260: 12/12 | H260: 40 - IMPIANTISTICO | I260: CENTRALE | J260: IMPIANTO HVAC | K260: OPERA: TUBAZIONE DI LEGA FERROSA ACCIAIO NERO; FUNZIONE: DISTRIBUZIONE ACQUA; IMPIEGO: RETE IDRICA; DIAMETRO NOMINALE (Ø) [MM] = 32 | SPESSORE [MM] = 2,6. | L260: OPERA: TUBAZIONE DI LEGA FERROSA ACCIAIO NERO; FUNZIONE: DISTRIBUZIONE ACQUA; IMPIEGO: RETE IDRICA; DIAMETRO NOMINALE (Ø) [MM] = 32 | SPESSORE [MM] = 2,6. LAVORO: POSA. SPECIFICHE TECNICHE: TUBO SENZA SALDATURA. OP TUBAZIONE DI LEGA FERROSA ACCIAIO NERO; FUNZIONE: DISTRIBUZIONE ACQUA; IMPIEGO: RETE IDRICA; DIAMETRO NOMINALE (Ø) [MM] = 32 | SPESSORE [MM] = 2,6. SPECIFICHE TECNICHE: TUBO SENZA SALDATURA. RM TUBO DI LEGA FERROSA ACCIAIO NERO; FUNZIONE: DISTRIBUZIONE ACQUA; IMPIEGO: RETE IDRICA; DIAMETRO NOMINALE (Ø) [MM] = 32 | SPESSORE [MM] = 2,6 SPECIFICHE TECNICHE: TUBO SENZA SALDATURA LV POSA. | M260: M | N260: 50 | O260: 31.42 | P260: 1571 | S260: =IF(AND(Q260<>"",R260<>""),Q260*R260,"") | T260: =IF(S260="",P260,S260) | U260: 0 | V260: =$T260*U260 | W260: 0.25 | X260: =$T260*W260 | Y260: 0 | Z260: =$T260*Y260 | AA260: 0 | AB260: =$T260*AA260 | AC260: 0 | AD260: =$T260*AC260 | AE260: 0 | AF260: =$T260*AE260 | AG260: 0 | AH260: =$T260*AG260 | AI260: =U260+W260+Y260+AA260+AC260+AE260+AG260 | AJ260: =V260+X260+Z260+AB260+AD260+AF260+AH260
